Workbook

Sheet Active users
A1: Week № | B1: Active Users | C1: Installs
A2: 44 | B2: 290532 | C2: 23612
A3: 43 | B3: 291486 | C3: 24301
A4: 42 | B4: 286578 | C4: 24460
A5: 41 | B5: 287257 | C5: 24277
A6: 40 | B6: 290068 | C6: 25293
A7: 39 | B7: 293688 | C7: 29262
A8: 38 | B8: 290579 | C8: 28848
A9: 37 | B9: 287348 | C9: 28741
A10: 36 | B10: 276711 | C10: 22074
A11: 35 | B11: 280392 | C11: 24252
A12: 34 | B12: 281868 | C12: 28525
A13: 33 | B13: 273532 | C13: 30221
... A45: 1 | B45: 69564 | C45: 18371

Sheet Users Retention Rate
A1: Users Retention Rate
B2: Weeks Since Install | C2: 1 | D2: 2 | E2: 3 | F2: 4 | G2: 5 | H2: 6 | I2: 7 | J2: 8 | K2: 9 | L2: 10 | M2: 11 | N2: 12 | O2: 13 | P2: 14 | Q2: 15 | R2: 16 | S2: 17 | T2: 18 | U2: 19 | V2: 20 | W2: 21 | X2: 22 | Y2: 23 | Z2: 24 | AA2: 25 | AB2: 26 | AC2: 27 | AD2: 28 | AE2: 29 | AF2: 30 | AG2: 31 | AH2: 32 | AI2: 33 | AJ2: 34 | AK2: 35 | AL2: 36 | AM2: 37 | AN2: 38 | AO2: 39 | AP2: 40 | AQ2: 41 | AR2: 42 | AS2: 43 | AT2: 44
A4: Week of installs, № | B4: Number of installs
A5: 44 | B5: 23612 | C5: 0.5199
A6: 43 | B6: 24301 | C6: 0.5586 | D6: 0.4447
A7: 42 | B7: 24460 | C7: 0.5394 | D7: 0.4726 | E7: 0.3883
A8: 41 | B8: 24277 | C8: 0.5277 | D8: 0.4588 | E8: 0.42 | F8: 0.3504
A9: 40 | B9: 25293 | C9: 0.5185 | D9: 0.4515 | E9: 0.4085 | F9: 0.3881 | G9: 0.3166
A10: 39 | B10: 29262 | C10: 0.551 | D10: 0.4721 | E10: 0.4246 | F10: 0.3941 | G10: 0.369 | H10: 0.3097
A11: 38 | B11: 28848 | C11: 0.5524 | D11: 0.4754 | E11: 0.4234 | F11: 0.3921 | G11: 0.3601 | H11: 0.3407 | I11: 0.2894
A12: 37 | B12: 28741 | C12: 0.4514 | D12: 0.3818 | E12: 0.3455 | F12: 0.3134 | G12: 0.2865 | H12: 0.2608 | I12: 0.2528 | J12: 0.207
A13: 36 | B13: 22074 | C13: 0.5142 | D13: 0.4473 | E13: 0.4032 | F13: 0.3798 | G13: 0.3385 | H13: 0.3169 | I13: 0.297 | J13: 0.281 | K13: 0.2427
A14: 35 | B14: 24252 | C14: 0.5672 | D14: 0.5028 | E14: 0.4569 | F14: 0.4279 | G14: 0.3868 | H14: 0.3598 | I14: 0.3408 | J14: 0.3229 | K14: 0.3093 | L14: 0.2653
A15: 34 | B15: 28525 | C15: 0.5887 | D15: 0.5229 | E15: 0.4823 | F15: 0.4531 | G15: 0.4176 | H15: 0.3883 | I15: 0.3598 | J15: 0.3451 | K15: 0.3301 | L15: 0.3151 | M15: 0.2764
A16: 33 | B16: 30221 | C16: 0.6051 | D16: 0.5333 | E16: 0.4905 | F16: 0.4684 | G16: 0.4381 | H16: 0.4086 | I16: 0.3827 | J16: 0.3592 | K16: 0.34 | L16: 0.3231 | M16: 0.314 | N16: 0.2729
A17: 32 | B17: 26927 | C17: 0.5868 | D17: 0.5224 | E17: 0.484 | F17: 0.4555 | G17: 0.428 | H17: 0.3998 | I17: 0.3827 | J17: 0.3533 | K17: 0.3323 | L17: 0.3192 | M17: 0.3017 | N17: 0.2908 | O17: 0.2528
A18: 31 | B18: 26498 | C18: 0.5734 | D18: 0.5208 | E18: 0.4811 | F18: 0.4498 | G18: 0.4212 | H18: 0.3996 | I18: 0.3808 | J18: 0.3601 | K18: 0.3374 | L18: 0.3176 | M18: 0.3074 | N18: 0.2922 | O18: 0.2826 | P18: 0.2485
A19: 30 | B19: 27814 | C19: 0.5574 | D19: 0.5059 | E19: 0.4746 | F19: 0.4508 | G19: 0.4167 | H19: 0.3909 | I19: 0.3761 | J19: 0.3589 | K19: 0.3408 | L19: 0.3207 | M19: 0.3014 | N19: 0.2886 | O19: 0.2767 | P19: 0.2655 | Q19: 0.2344
A20: 29 | B20: 27664 | C20: 0.5413 | D20: 0.4925 | E20: 0.4703 | F20: 0.4541 | G20: 0.4239 | H20: 0.3991 | I20: 0.378 | J20: 0.3646 | K20: 0.3459 | L20: 0.3253 | M20: 0.3145 | N20: 0.2948 | O20: 0.2829 | P20: 0.2721 | Q20: 0.264 | R20: 0.2287
A21: 28 | B21: 26366 | C21: 0.5071 | D21: 0.4794 | E21: 0.4805 | F21: 0.4967 | G21: 0.4619 | H21: 0.436 | I21: 0.4099 | J21: 0.3914 | K21: 0.3758 | L21: 0.3595 | M21: 0.3421 | N21: 0.3236 | O21: 0.3051 | P21: 0.2906 | Q21: 0.2799 | R21: 0.2712 | S21: 0.2375
A22: 27 | B22: 26140 | C22: 0.5041 | D22: 0.47 | E22: 0.4666 | F22: 0.4742 | G22: 0.4473 | H22: 0.428 | I22: 0.4065 | J22: 0.38 | K22: 0.3611 | L22: 0.3536 | M22: 0.338 | N22: 0.3222 | O22: 0.3045 | P22: 0.2895 | Q22: 0.2786 | R22: 0.2662 | S22: 0.2583 | T22: 0.228
A23: 26 | B23: 28800 | C23: 0.4185 | D23: 0.3989 | E23: 0.4109 | F23: 0.4174 | G23: 0.3974 | H23: 0.3866 | I23: 0.3726 | J23: 0.3579 | K23: 0.342 | L23: 0.3241 | M23: 0.3169 | N23: 0.3069 | O23: 0.2927 | P23: 0.2775 | Q23: 0.2596 | R23: 0.2531 | S23: 0.243 | T23: 0.233 | U23: 0.209
A24: 25 | B24: 31688 | C24: 0.5434 | D24: 0.4876 | E24: 0.4713 | F24: 0.4759 | G24: 0.4453 | H24: 0.4262 | I24: 0.4087 | J24: 0.3941 | K24: 0.3769 | L24: 0.3593 | M24: 0.3426 | N24: 0.3318 | O24: 0.3198 | P24: 0.3061 | Q24: 0.2893 | R24: 0.2758 | S24: 0.2668 | T24: 0.2542 | U24: 0.2504 | V24: 0.2184
A25: 24 | B25: 30330 | C25: 0.5861 | D25: 0.5136 | E25: 0.481 | F25: 0.4725 | G25: 0.4425 | H25: 0.4212 | I25: 0.4041 | J25: 0.389 | K25: 0.3748 | L25: 0.3582 | M25: 0.3395 | N25: 0.3218 | O25: 0.3203 | P25: 0.3076 | Q25: 0.2919 | R25: 0.2748 | S25: 0.2628 | T25: 0.2525 | U25: 0.244 | V25: 0.2396 | W25: 0.2099
A26: 23 | B26: 24364 | C26: 0.585 | D26: 0.5327 | E26: 0.4932 | F26: 0.4654 | G26: 0.4413 | H26: 0.4238 | I26: 0.4043 | J26: 0.3868 | K26: 0.3741 | L26: 0.3605 | M26: 0.3436 | N26: 0.3243 | O26: 0.3128 | P26: 0.3061 | Q26: 0.2915 | R26: 0.2787 | S26: 0.2654 | T26: 0.2537 | U26: 0.2454 | V26: 0.2373 | W26: 0.2303 | X26: 0.2015
A27: 22 | B27: 21213 | C27: 0.571 | D27: 0.5259 | E27: 0.5017 | F27: 0.4741 | G27: 0.4378 | H27: 0.4254 | I27: 0.4041 | J27: 0.3826 | K27: 0.368 | L27: 0.359 | M27: 0.3458 | N27: 0.3318 | O27: 0.3104 | P27: 0.3044 | Q27: 0.296 | R27: 0.2814 | S27: 0.2729 | T27: 0.2567 | U27: 0.2419 | V27: 0.236 | W27: 0.2259 | X27: 0.223 | Y27: 0.1979
A28: 21 | B28: 24263 | C28: 0.5826 | D28: 0.5349 | E28: 0.5099 | F28: 0.4886 | G28: 0.4479 | H28: 0.4213 | I28: 0.4097 | J28: 0.3873 | K28: 0.3679 | L28: 0.3566 | M28: 0.3451 | N28: 0.3331 | O28: 0.3184 | P28: 0.3007 | Q28: 0.2912 | R28: 0.2858 | S28: 0.2773 | T28: 0.2646 | U28: 0.2514 | V28: 0.2391 | W28: 0.233 | X28: 0.2245 | Y28: 0.2187 | Z28: 0.1909
A29: 20 | B29: 24753 | C29: 0.6106 | D29: 0.5559 | E29: 0.5329 | F29: 0.5221 | G29: 0.4877 | H29: 0.4491 | I29: 0.4253 | J29: 0.4177 | K29: 0.3934 | L29: 0.3737 | M29: 0.3602 | N29: 0.3489 | O29: 0.3375 | P29: 0.3223 | Q29: 0.3069 | R29: 0.2924 | S29: 0.2874 | T29: 0.2767 | U29: 0.2642 | V29: 0.2535 | W29: 0.2388 | X29: 0.2301 | Y29: 0.223 | Z29: 0.2172 | AA29: 0.1914
A30: 19 | B30: 18337 | C30: 0.5665 | D30: 0.5177 | E30: 0.5067 | F30: 0.5073 | G30: 0.472 | H30: 0.4444 | I30: 0.4139 | J30: 0.3925 | K30: 0.3816 | L30: 0.3673 | M30: 0.3471 | N30: 0.3373 | O30: 0.3264 | P30: 0.3112 | Q30: 0.2985 | R30: 0.2861 | S30: 0.2743 | T30: 0.2726 | U30: 0.2572 | V30: 0.2494 | W30: 0.2351 | X30: 0.2222 | Y30: 0.2144 | Z30: 0.2088 | AA30: 0.1994 | AB30: 0.1768
A31: 18 | B31: 14603 | C31: 0.5395 | D31: 0.4913 | E31: 0.4586 | F31: 0.4509 | G31: 0.4164 | H31: 0.3933 | I31: 0.3714 | J31: 0.3421 | K31: 0.3252 | L31: 0.3213 | M31: 0.306 | N31: 0.2918 | O31: 0.2799 | P31: 0.268 | Q31: 0.2612 | R31: 0.2548 | S31: 0.2381 | T31: 0.2302 | U31: 0.228 | V31: 0.2179 | W31: 0.2087 | X31: 0.1998 | Y31: 0.1878 | Z31: 0.1817 | AA31: 0.176 | AB31: 0.1707 | AC31: 0.1494
A32: 17 | B32: 14565 | C32: 0.5486 | D32: 0.4893 | E32: 0.4644 | F32: 0.4413 | G32: 0.4121 | H32: 0.3926 | I32: 0.3789 | J32: 0.3541 | K32: 0.3255 | L32: 0.3099 | M32: 0.3052 | N32: 0.2893 | O32: 0.2787 | P32: 0.268 | Q32: 0.2595 | R32: 0.2546 | S32: 0.2402 | T32: 0.2276 | U32: 0.2231 | V32: 0.2178 | W32: 0.2093 | X32: 0.1981 | Y32: 0.1905 | Z32: 0.183 | AA32: 0.1775 | AB32: 0.1701 | AC32: 0.1645 | AD32: 0.1413
A33: 16 | B33: 14336 | C33: 0.5566 | D33: 0.4961 | E33: 0.4723 | F33: 0.4614 | G33: 0.4192 | H33: 0.3966 | I33: 0.3809 | J33: 0.3686 | K33: 0.3473 | L33: 0.3209 | M33: 0.3037 | N33: 0.2958 | O33: 0.2889 | P33: 0.2779 | Q33: 0.2662 | R33: 0.2573 | S33: 0.2529 | T33: 0.2401 | U33: 0.2242 | V33: 0.2151 | W33: 0.2139 | X33: 0.2074 | Y33: 0.1971 | Z33: 0.1872 | AA33: 0.1742 | AB33: 0.1703 | AC33: 0.1659 | AD33: 0.1611 | AE33: 0.1391
A34: 15 | B34: 27968 | C34: 0.4677 | D34: 0.5509 | E34: 0.6738 | F34: 0.7392 | G34: 0.6854 | H34: 0.6335 | I34: 0.5973 | J34: 0.574 | K34: 0.5491 | L34: 0.5229 | M34: 0.4959 | N34: 0.4759 | O34: 0.4573 | P34: 0.436 | Q34: 0.4121 | R34: 0.3987 | S34: 0.3882 | T34: 0.38 | U34: 0.3608 | V34: 0.345 | W34: 0.3306 | X34: 0.3239 | Y34: 0.3136 | Z34: 0.301 | AA34: 0.2874 | AB34: 0.2736 | AC34: 0.2658 | AD34: 0.2583 | AE34: 0.251 | AF34: 0.2329
A35: 14 | B35: 14311 | C35: 0.6327 | D35: 0.5712 | E35: 0.5445 | F35: 0.5322 | G35: 0.5004 | H35: 0.4773 | I35: 0.4494 | J35: 0.4304 | K35: 0.4163 | L35: 0.4004 | M35: 0.3842 | N35: 0.3594 | O35: 0.3476 | P35: 0.3318 | Q35: 0.3188 | R35: 0.3089 | S35: 0.2995 | T35: 0.2919 | U35: 0.2851 | V35: 0.2769 | W35: 0.2606 | X35: 0.2465 | Y35: 0.247 | Z35: 0.2357 | AA35: 0.2327 | AB35: 0.2192 | AC35: 0.2107 | AD35: 0.2026 | AE35: 0.1976 | AF35: 0.1923 | AG35: 0.1724
A36: 13 | B36: 11567 | C36: 0.6047 | D36: 0.5439 | E36: 0.5032 | F36: 0.4865 | G36: 0.451 | H36: 0.4385 | I36: 0.4164 | J36: 0.3934 | K36: 0.3766 | L36: 0.3666 | M36: 0.3504 | N36: 0.3354 | O36: 0.3136 | P36: 0.3045 | Q36: 0.2926 | R36: 0.2835 | S36: 0.2687 | T36: 0.2607 | U36: 0.253 | V36: 0.251 | W36: 0.2417 | X36: 0.233 | Y36: 0.2233 | Z36: 0.2221 | AA36: 0.2118 | AB36: 0.2023 | AC36: 0.1932 | AD36: 0.1867 | AE36: 0.1791 | AF36: 0.1728 | AG36: 0.1694 | AH36: 0.1464
A37: 12 | B37: 14362 | C37: 0.4838 | D37: 0.4778 | E37: 0.45 | F37: 0.4286 | G37: 0.4013 | H37: 0.3906 | I37: 0.3855 | J37: 0.365 | K37: 0.3483 | L37: 0.3355 | M37: 0.3286 | N37: 0.3178 | O37: 0.3052 | P37: 0.2907 | Q37: 0.2787 | R37: 0.2706 | S37: 0.2598 | T37: 0.2543 | U37: 0.2459 | V37: 0.24 | W37: 0.2346 | X37: 0.227 | Y37: 0.2174 | Z37: 0.2097 | AA37: 0.2097 | AB37: 0.1991 | AC37: 0.1928 | AD37: 0.189 | AE37: 0.1775 | AF37: 0.1729 | AG37: 0.1656 | AH37: 0.1625 | AI37: 0.1422
A38: 11 | B38: 18709 | C38: 0.4425 | D38: 0.3677 | E38: 0.3803 | F38: 0.3711 | G38: 0.3492 | H38: 0.3389 | I38: 0.331 | J38: 0.3281 | K38: 0.319 | L38: 0.302 | M38: 0.2931 | N38: 0.2847 | O38: 0.2814 | P38: 0.269 | Q38: 0.2589 | R38: 0.2502 | S38: 0.2404 | T38: 0.231 | U38: 0.2275 | V38: 0.2212 | W38: 0.2158 | X38: 0.2117 | Y38: 0.2089 | Z38: 0.1982 | AA38: 0.1925 | AB38: 0.1928 | AC38: 0.1848 | AD38: 0.1776 | AE38: 0.1684 | AF38: 0.1614 | AG38: 0.1546 | AH38: 0.1493 | AI38: 0.145 | AJ38: 0.1279
A39: 10 | B39: 21946 | C39: 0.5622 | D39: 0.5122 | E39: 0.4562 | F39: 0.4486 | G39: 0.4166 | H39: 0.4003 | I39: 0.3839 | J39: 0.3701 | K39: 0.3644 | L39: 0.3481 | M39: 0.3318 | N39: 0.3192 | O39: 0.3123 | P39: 0.3012 | Q39: 0.2922 | R39: 0.2796 | S39: 0.2643 | T39: 0.2579 | U39: 0.253 | V39: 0.2441 | W39: 0.2382 | X39: 0.2341 | Y39: 0.2303 | Z39: 0.2231 | AA39: 0.2124 | AB39: 0.2048 | AC39: 0.2015 | AD39: 0.1974 | AE39: 0.1889 | AF39: 0.1828 | AG39: 0.1715 | AH39: 0.1663 | AI39: 0.1602 | AJ39: 0.1581 | AK39: 0.1328
A40: 9 | B40: 13502 | C40: 0.6606 | D40: 0.5739 | E40: 0.5384 | F40: 0.4979 | G40: 0.4645 | H40: 0.4461 | I40: 0.4229 | J40: 0.4035 | K40: 0.3866 | L40: 0.3856 | M40: 0.3642 | N40: 0.3434 | O40: 0.339 | P40: 0.3237 | Q40: 0.3168 | R40: 0.3024 | S40: 0.2895 | T40: 0.2774 | U40: 0.2651 | V40: 0.2612 | W40: 0.2577 | X40: 0.25 | Y40: 0.2478 | Z40: 0.2446 | AA40: 0.2327 | AB40: 0.2271 | AC40: 0.2206 | AD40: 0.2138 | AE40: 0.2092 | AF40: 0.2032 | AG40: 0.192 | AH40: 0.1795 | AI40: 0.1735 | AJ40: 0.1718 | AK40: 0.1673 | AL40: 0.1459
A41: 8 | B41: 13102 | C41: 0.6361 | D41: 0.6196 | E41: 0.5572 | F41: 0.5324 | G41: 0.4824 | H41: 0.4649 | I41: 0.4376 | J41: 0.4227 | K41: 0.4055 | L41: 0.3899 | M41: 0.3843 | N41: 0.3703 | O41: 0.3486 | P41: 0.3375 | Q41: 0.3261 | R41: 0.3187 | S41: 0.3105 | T41: 0.292 | U41: 0.2822 | V41: 0.2755 | W41: 0.2715 | X41: 0.2622 | Y41: 0.2571 | Z41: 0.2528 | AA41: 0.2478 | AB41: 0.2368 | AC41: 0.2289 | AD41: 0.2194 | AE41: 0.217 | AF41: 0.213 | AG41: 0.2015 | AH41: 0.1961 | AI41: 0.1847 | AJ41: 0.1774 | AK41: 0.1696 | AL41: 0.1672 | AM41: 0.147
...

Sheet Emails sent
A1: Emails sent
B2: Weeks Since Install | C2: 1 | D2: 2 | E2: 3 | F2: 4 | G2: 5 | H2: 6 | I2: 7 | J2: 8 | K2: 9 | L2: 10 | M2: 11 | N2: 12 | O2: 13 | P2: 14 | Q2: 15 | R2: 16 | S2: 17 | T2: 18 | U2: 19 | V2: 20 | W2: 21 | X2: 22 | Y2: 23 | Z2: 24 | AA2: 25 | AB2: 26 | AC2: 27 | AD2: 28 | AE2: 29 | AF2: 30 | AG2: 31 | AH2: 32 | AI2: 33 | AJ2: 34 | AK2: 35 | AL2: 36 | AM2: 37 | AN2: 38 | AO2: 39 | AP2: 40 | AQ2: 41 | AR2: 42 | AS2: 43 | AT2: 44
C3: Emails sent:
A4: Week of installs, № | B4: Number of installs
A5: 44 | B5: 23612 | C5: 1227632
A6: 43 | B6: 24301 | C6: 1357449 | D6: 1080711
A7: 42 | B7: 24460 | C7: 1319418 | D7: 1155992 | E7: 949801
A8: 41 | B8: 24277 | C8: 1281076 | D8: 1113773 | E8: 1019587 | F8: 850722
A9: 40 | B9: 25293 | C9: 1311443 | D9: 1141968 | E9: 1033202 | F9: 981579 | G9: 800806
A10: 39 | B10: 29262 | C10: 1612295 | D10: 1381495 | E10: 1242523 | F10: 1153155 | G10: 1079821 | H10: 906168
A11: 38 | B11: 28848 | C11: 1593527 | D11: 1371441 | E11: 1221391 | F11: 1131059 | G11: 1038810 | H11: 982898 | I11: 834855
A12: 37 | B12: 28741 | C12: 1297300 | D12: 1097352 | E12: 993019 | F12: 900757 | G12: 823370 | H12: 749583 | I12: 726548 | J12: 594969
A13: 36 | B13: 22074 | C13: 1135031 | D13: 987397 | E13: 890021 | F13: 838426 | G13: 747131 | H13: 699514 | I13: 655678 | J13: 620330 | K13: 535751
A14: 35 | B14: 24252 | C14: 1375576 | D14: 1219418 | E14: 1108079 | F14: 1037701 | G14: 938125 | H14: 872662 | I14: 826523 | J14: 783100 | K14: 750039 | L14: 643382
A15: 34 | B15: 28525 | C15: 1679291 | D15: 1491613 | E15: 1375858 | F15: 1292500 | G15: 1191186 | H15: 1107638 | I15: 1026251 | J15: 984333 | K15: 941604 | L15: 898825 | M15: 788433
A16: 33 | B16: 30221 | C16: 1828699 | D16: 1611742 | E16: 1482259 | F16: 1415600 | G16: 1324010 | H16: 1234749 | I16: 1156532 | J16: 1085470 | K16: 1027520 | L16: 976396 | M16: 948900 | N16: 824773
A17: 32 | B17: 26927 | C17: 1580102 | D17: 1406634 | E17: 1303267 | F17: 1226511 | G17: 1152504 | H17: 1076496 | I17: 1030514 | J17: 951311 | K17: 894821 | L17: 859476 | M17: 812382 | N17: 783050 | O17: 680706
A18: 31 | B18: 26498 | C18: 2279055 | D18: 2069948 | E18: 1912176 | F18: 1787792 | G18: 1674124 | H18: 1588370 | I18: 1513405 | J18: 1431327 | K18: 1340997 | L18: 1262396 | M18: 1221733 | N18: 1161497 | O18: 1123224 | P18: 987762
A19: 30 | B19: 27814 | C19: 2325600 | D19: 2110732 | E19: 1980177 | F19: 1880772 | G19: 1738445 | H19: 1630768 | I19: 1569076 | J19: 1497374 | K19: 1421860 | L19: 1338013 | M19: 1257443 | N19: 1204075 | O19: 1154378 | P19: 1107758 | Q19: 978043
A20: 29 | B20: 27664 | C20: 2246265 | D20: 2043820 | E20: 1951480 | F20: 1884366 | G20: 1759005 | H20: 1656125 | I20: 1568515 | J20: 1512910 | K20: 1435391 | L20: 1349908 | M20: 1305080 | N20: 1223243 | O20: 1173896 | P20: 1129033 | Q20: 1095438 | R20: 949092
A21: 28 | B21: 26366 | C21: 2005552 | D21: 1896017 | E21: 1900346 | F21: 1964393 | G21: 1826705 | H21: 1724434 | I21: 1621064 | J21: 1548020 | K21: 1486159 | L21: 1421874 | M21: 1353020 | N21: 1279874 | O21: 1206551 | P21: 1149325 | Q21: 1107060 | R21: 1072462 | S21: 939360
A22: 27 | B22: 26140 | C22: 1976575 | D22: 1842840 | E22: 1829549 | F22: 1859419 | G22: 1753773 | H22: 1678166 | I22: 1593898 | J22: 1489959 | K22: 1415900 | L22: 1386429 | M22: 1325239 | N22: 1263314 | O22: 1193968 | P22: 1135146 | Q22: 1092451 | R22: 1043744 | S22: 1012785 | T22: 894019
A23: 26 | B23: 28800 | C23: 1807941 | D23: 1723157 | E23: 1775059 | F23: 1803132 | G23: 1716746 | H23: 1670033 | I23: 1609611 | J23: 1546248 | K23: 1477518 | L23: 1400078 | M23: 1369033 | N23: 1325859 | O23: 1264524 | P23: 1198806 | Q23: 1121419 | R23: 1093294 | S23: 1049724 | T23: 1006468 | U23: 902854
A24: 25 | B24: 31688 | C24: 2582847 | D24: 2317705 | E24: 2240186 | F24: 2261999 | G24: 2116625 | H24: 2025718 | I24: 1942633 | J24: 1873125 | K24: 1791439 | L24: 1707776 | M24: 1628415 | N24: 1577134 | O24: 1520194 | P24: 1455017 | Q24: 1375037 | R24: 1310980 | S24: 1268044 | T24: 1208210 | U24: 1190294 | V24: 1038133
A25: 24 | B25: 30330 | C25: 2666364 | D25: 2336595 | E25: 2188341 | F25: 2149685 | G25: 2013204 | H25: 1916264 | I25: 1838429 | J25: 1769657 | K25: 1705164 | L25: 1629626 | M25: 1544555 | N25: 1463991 | O25: 1457187 | P25: 1399525 | Q25: 1327908 | R25: 1250264 | S25: 1195637 | T25: 1148664 | U25: 1110169 | V25: 1090054 | W25: 954897
A26: 23 | B26: 24364 | C26: 997727 | D26: 908475 | E26: 841119 | F26: 793707 | G26: 752663 | H26: 722744 | I26: 689548 | J26: 659681 | K26: 638021 | L26: 614793 | M26: 586038 | N26: 553108 | O26: 533481 | P26: 522024 | Q26: 497135 | R26: 475330 | S26: 452595 | T26: 432684 | U26: 418652 | V26: 404687 | W26: 392728 | X26: 343613
A27: 22 | B27: 21213 | C27: 847831 | D27: 780892 | E27: 745038 | F27: 704010 | G27: 650094 | H27: 631665 | I27: 600109 | J27: 568105 | K27: 546441 | L27: 533119 | M27: 513418 | N27: 492712 | O27: 460950 | P27: 451929 | Q27: 439446 | R27: 417824 | S27: 405145 | T27: 381143 | U27: 359176 | V27: 350411 | W27: 335390 | X27: 331084 | Y27: 293840
A28: 21 | B28: 24263 | C28: 989500 | D28: 908369 | E28: 866051 | F28: 829815 | G28: 760686 | H28: 715586 | I28: 695817 | J28: 657850 | K28: 624804 | L28: 605650 | M28: 586104 | N28: 565678 | O28: 540797 | P28: 510694 | Q28: 494579 | R28: 485408 | S28: 470980 | T28: 449439 | U28: 427029 | V28: 406035 | W28: 395701 | X28: 381243 | Y28: 371483 | Z28: 324229
A29: 20 | B29: 24753 | C29: 1057971 | D29: 963239 | E29: 923316 | F29: 904657 | G29: 845057 | H29: 778203 | I29: 736890 | J29: 723775 | K29: 681586 | L29: 647521 | M29: 624163 | N29: 604494 | O29: 584807 | P29: 558458 | Q29: 531777 | R29: 506637 | S29: 497948 | T29: 479403 | U29: 457826 | V29: 439217 | W29: 413877 | X29: 398781 | Y29: 386384 | Z29: 376339 | AA29: 331654
A30: 19 | B30: 18337 | C30: 727217 | D30: 664548 | E30: 650337 | F30: 651175 | G30: 605819 | H30: 570434 | I30: 531251 | J30: 503798 | K30: 489773 | L30: 471437 | M30: 445526 | N30: 432927 | O30: 418877 | P30: 399437 | Q30: 383154 | R30: 367219 | S30: 352087 | T30: 349927 | U30: 330135 | V30: 320131 | W30: 301688 | X30: 285169 | Y30: 275250 | Z30: 268017 | AA30: 255929 | AB30: 227021
A31: 18 | B31: 14603 | C31: 551474 | D31: 502221 | E31: 468818 | F31: 460984 | G31: 425669 | H31: 402012 | I31: 379652 | J31: 349683 | K31: 332402 | L31: 328454 | M31: 312783 | N31: 298221 | O31: 286170 | P31: 273956 | Q31: 266951 | R31: 260436 | S31: 243431 | T31: 235333 | U31: 233011 | V31: 222794 | W31: 213366 | X31: 204305 | Y31: 191973 | Z31: 185772 | AA31: 179948 | AB31: 174450 | AC31: 152824
A32: 17 | B32: 14565 | C32: 559303 | D32: 498926 | E32: 473536 | F32: 449956 | G32: 420098 | H32: 400236 | I32: 386340 | J32: 360949 | K32: 331890 | L32: 315996 | M32: 311187 | N32: 294981 | O32: 284107 | P32: 273205 | Q32: 264674 | R32: 259607 | S32: 244870 | T32: 231940 | U32: 227463 | V32: 222050 | W32: 213364 | X32: 201930 | Y32: 194233 | Z32: 186588 | AA32: 180918 | AB32: 173429 | AC32: 167653 | AD32: 144071
A33: 16 | B33: 14336 | C33: 558535 | D33: 497887 | E33: 473921 | F33: 463124 | G33: 420681 | H33: 398008 | I33: 382275 | J33: 369836 | K33: 348550 | L33: 322040 | M33: 304837 | N33: 296907 | O33: 289931 | P33: 278857 | Q33: 267118 | R33: 258256 | S33: 253800 | T33: 240909 | U33: 224995 | V33: 215895 | W33: 214571 | X33: 208122 | Y33: 197851 | Z33: 187924 | AA33: 174817 | AB33: 170870 | AC33: 166443 | AD33: 161600 | AE33: 139586
A34: 15 | B34: 27968 | C34: 915670 | D34: 1078603 | E34: 1319055 | F34: 1447150 | G34: 1341794 | H34: 1240229 | I34: 1169293 | J34: 1123668 | K34: 1075034 | L34: 1023661 | M34: 970779 | N34: 931760 | O34: 895324 | P34: 853554 | Q34: 806726 | R34: 780589 | S34: 760059 | T34: 743921 | U34: 706362 | V34: 675391 | W34: 647264 | X34: 634189 | Y34: 613863 | Z34: 589295 | AA34: 562654 | AB34: 535611 | AC34: 520399 | AD34: 505670 | AE34: 491405 | AF34: 455939
A35: 14 | B35: 14311 | C35: 633857 | D35: 572185 | E35: 545443 | F35: 533125 | G35: 501227 | H35: 478153 | I35: 450210 | J35: 431164 | K35: 417093 | L35: 401125 | M35: 384871 | N35: 360020 | O35: 348219 | P35: 332398 | Q35: 319292 | R35: 309458 | S35: 299993 | T35: 292443 | U35: 285619 | V35: 277406 | W35: 261068 | X35: 246981 | Y35: 247505 | Z35: 236071 | AA35: 233052 | AB35: 219551 | AC35: 211025 | AD35: 202848 | AE35: 197886 | AF35: 192660 | AG35: 172740
A36: 13 | B36: 11567 | C36: 489699 | D36: 440397 | E36: 407514 | F36: 393878 | G36: 365191 | H36: 355012 | I36: 337123 | J36: 318480 | K36: 304949 | L36: 296813 | M36: 283702 | N36: 271588 | O36: 253879 | P36: 246494 | Q36: 236985 | R36: 229512 | S36: 217594 | T36: 211128 | U36: 204836 | V36: 203181 | W36: 195759 | X36: 188727 | Y36: 180814 | Z36: 179894 | AA36: 171512 | AB36: 163825 | AC36: 156487 | AD36: 151218 | AE36: 145061 | AF36: 139922 | AG36: 137137 | AH36: 118483
A37: 12 | B37: 14362 | C37: 486398 | D37: 480306 | E37: 452387 | F37: 430892 | G37: 403371 | H37: 392701 | I37: 387576 | J37: 366975 | K37: 350084 | L37: 337275 | M37: 330242 | N37: 319493 | O37: 306850 | P37: 292293 | Q37: 280200 | R37: 271923 | S37: 261156 | T37: 255634 | U37: 247280 | V37: 241277 | W37: 235850 | X37: 228169 | Y37: 218606 | Z37: 210822 | AA37: 210823 | AB37: 200105 | AC37: 193793 | AD37: 189985 | AE37: 178360 | AF37: 173748 | AG37: 166477 | AH37: 163317 | AI37: 142970
A38: 11 | B38: 18709 | C38: 579552 | D38: 481484 | E38: 498073 | F38: 485968 | G38: 457279 | H38: 443775 | I38: 433502 | J38: 429712 | K38: 417737 | L38: 395490 | M38: 383868 | N38: 372818 | O38: 368626 | P38: 352310 | Q38: 339060 | R38: 327675 | S38: 314880 | T38: 302582 | U38: 297808 | V38: 289678 | W38: 282556 | X38: 277334 | Y38: 273543 | Z38: 259599 | AA38: 252042 | AB38: 252540 | AC38: 241912 | AD38: 232585 | AE38: 220515 | AF38: 211453 | AG38: 202430 | AH38: 195562 | AI38: 189875 | AJ38: 167477
A39: 10 | B39: 21946 | C39: 616961 | D39: 562044 | E39: 500614 | F39: 492216 | G39: 457128 | H39: 439217 | I39: 421190 | J39: 406139 | K39: 399853 | L39: 381955 | M39: 364140 | N39: 350198 | O39: 342715 | P39: 330481 | Q39: 320672 | R39: 306751 | S39: 289970 | T39: 282968 | U39: 277536 | V39: 267868 | W39: 261418 | X39: 256870 | Y39: 252645 | Z39: 244866 | AA39: 233069 | AB39: 224709 | AC39: 221112 | AD39: 216636 | AE39: 207230 | AF39: 200582 | AG39: 188232 | AH39: 182499 | AI39: 175791 | AJ39: 173509 | AK39: 145730
A40: 9 | B40: 13502 | C40: 445906 | D40: 387394 | E40: 363431 | F40: 336149 | G40: 313630 | H40: 301070 | I40: 285499 | J40: 272390 | K40: 260992 | L40: 260317 | M40: 245862 | N40: 231906 | O40: 228910 | P40: 218547 | Q40: 213826 | R40: 204173 | S40: 195460 | T40: 187228 | U40: 178988 | V40: 176389 | W40: 173872 | X40: 168811 | Y40: 167361 | Z40: 165162 | AA40: 157094 | AB40: 153339 | AC40: 149016 | AD40: 144348 | AE40: 141258 | AF40: 137260 | AG40: 129612 | AH40: 121174 | AI40: 117177 | AJ40: 115949 | AK40: 112906 | AL40: 98521
...

Sheet Emails clicks
A1: Emails clicks
B2: Weeks Since Install | C2: 1 | D2: 2 | E2: 3 | F2: 4 | G2: 5 | H2: 6 | I2: 7 | J2: 8 | K2: 9 | L2: 10 | M2: 11 | N2: 12 | O2: 13 | P2: 14 | Q2: 15 | R2: 16 | S2: 17 | T2: 18 | U2: 19 | V2: 20 | W2: 21 | X2: 22 | Y2: 23 | Z2: 24 | AA2: 25 | AB2: 26 | AC2: 27 | AD2: 28 | AE2: 29 | AF2: 30 | AG2: 31 | AH2: 32 | AI2: 33 | AJ2: 34 | AK2: 35 | AL2: 36 | AM2: 37 | AN2: 38 | AO2: 39 | AP2: 40 | AQ2: 41 | AR2: 42 | AS2: 43 | AT2: 44
C3: Emails clicks
A4: Week of installs, № | B4: Number of installs
A5: 44 | B5: 23612 | C5: 27008
A6: 43 | B6: 24301 | C6: 29864 | D6: 26153
A7: 42 | B7: 24460 | C7: 29027 | D7: 27975 | E7: 25075
A8: 41 | B8: 24277 | C8: 28184 | D8: 26953 | E8: 26917 | F8: 24331
A9: 40 | B9: 25293 | C9: 28852 | D9: 27636 | E9: 27277 | F9: 28073 | G9: 24665
A10: 39 | B10: 29262 | C10: 35470 | D10: 33432 | E10: 32803 | F10: 32980 | G10: 33258 | H10: 29904
A11: 38 | B11: 28848 | C11: 35058 | D11: 33189 | E11: 32245 | F11: 32348 | G11: 31995 | H11: 32436 | I11: 29387
A12: 37 | B12: 28741 | C12: 10378 | D12: 9657 | E12: 9533 | F12: 9368 | G12: 9222 | H12: 8995 | I12: 9300 | J12: 8092
A13: 36 | B13: 22074 | C13: 9080 | D13: 8689 | E13: 8544 | F13: 8720 | G13: 8368 | H13: 8394 | I13: 8393 | J13: 8436 | K13: 7715
A14: 35 | B14: 24252 | C14: 11005 | D14: 10731 | E14: 10638 | F14: 10792 | G14: 10507 | H14: 10472 | I14: 10579 | J14: 10650 | K14: 10801 | L14: 9779
A15: 34 | B15: 28525 | C15: 13434 | D15: 13126 | E15: 13208 | F15: 13442 | G15: 13341 | H15: 13292 | I15: 13136 | J15: 13387 | K15: 13559 | L15: 13662 | M15: 12615
A16: 33 | B16: 30221 | C16: 14630 | D16: 14183 | E16: 14230 | F16: 14722 | G16: 14829 | H16: 14817 | I16: 14804 | J16: 14762 | K16: 14796 | L16: 14841 | M16: 15182 | N16: 13856
A17: 32 | B17: 26927 | C17: 12641 | D17: 12378 | E17: 12511 | F17: 12756 | G17: 12908 | H17: 12918 | I17: 13191 | J17: 12938 | K17: 12885 | L17: 13064 | M17: 12998 | N17: 13155 | O17: 11980
A18: 31 | B18: 26498 | C18: 18232 | D18: 18216 | E18: 18357 | F18: 18593 | G18: 18750 | H18: 19060 | I18: 19372 | J18: 19466 | K18: 19310 | L18: 19188 | M18: 19548 | N18: 19513 | O18: 19769 | P18: 18175
A19: 30 | B19: 27814 | C19: 18605 | D19: 18574 | E19: 19010 | F19: 19560 | G19: 19471 | H19: 19569 | I19: 20084 | J19: 20364 | K19: 20475 | L19: 20338 | M19: 20119 | N19: 20228 | O19: 20317 | P19: 20383 | Q19: 18778
A20: 29 | B20: 27664 | C20: 17970 | D20: 17986 | E20: 18734 | F20: 19597 | G20: 19701 | H20: 19874 | I20: 20077 | J20: 20576 | K20: 20670 | L20: 20519 | M20: 20881 | N20: 20550 | O20: 20661 | P20: 20774 | Q20: 21032 | R20: 18982
A21: 28 | B21: 26366 | C21: 16044 | D21: 16685 | E21: 18243 | F21: 20430 | G21: 20459 | H21: 20693 | I21: 20750 | J21: 21053 | K21: 21401 | L21: 21612 | M21: 21648 | N21: 21502 | O21: 21235 | P21: 21148 | Q21: 21256 | R21: 21449 | S21: 19539
A22: 27 | B22: 26140 | C22: 15813 | D22: 16217 | E22: 17564 | F22: 19338 | G22: 19642 | H22: 20138 | I22: 20402 | J22: 20263 | K22: 20389 | L22: 21074 | M22: 21204 | N22: 21224 | O22: 21014 | P22: 20887 | Q22: 20975 | R22: 20875 | S22: 21066 | T22: 19311
A23: 26 | B23: 28800 | C23: 14464 | D23: 15164 | E23: 17041 | F23: 18753 | G23: 19228 | H23: 20040 | I23: 20603 | J23: 21029 | K23: 21276 | L23: 21281 | M23: 21905 | N23: 22274 | O23: 22256 | P23: 22058 | Q23: 21531 | R23: 21866 | S23: 21834 | T23: 21740 | U23: 20224
A24: 25 | B24: 31688 | C24: 38743 | D24: 38242 | E24: 40323 | F24: 44109 | G24: 44449 | H24: 45579 | I24: 46623 | J24: 47765 | K24: 48369 | L24: 48672 | M24: 48852 | N24: 49680 | O24: 50166 | P24: 50198 | Q24: 49501 | R24: 49162 | S24: 49454 | T24: 48933 | U24: 49992 | V24: 45159
A25: 24 | B25: 30330 | C25: 55994 | D25: 53975 | E25: 55146 | F25: 58686 | G25: 59188 | H25: 60362 | I25: 61771 | J25: 63177 | K25: 64455 | L25: 65022 | M25: 64871 | N25: 64562 | O25: 67322 | P25: 67597 | Q25: 66927 | R25: 65639 | S25: 65282 | T25: 65129 | U25: 65278 | V25: 66384 | W25: 60159
A26: 23 | B26: 24364 | C26: 20952 | D26: 20986 | E26: 21196 | F26: 21668 | G26: 22128 | H26: 22766 | I26: 23169 | J26: 23551 | K26: 24117 | L26: 24530 | M26: 24614 | N26: 24392 | O26: 24647 | P26: 25214 | Q26: 25056 | R26: 24955 | S26: 24712 | T26: 24533 | U26: 24617 | V26: 24645 | W26: 24742 | X26: 22369
A27: 22 | B27: 21213 | C27: 17804 | D27: 18039 | E27: 18775 | F27: 19219 | G27: 19113 | H27: 19897 | I27: 20164 | J27: 20281 | K27: 20655 | L27: 21271 | M27: 21564 | N27: 21729 | O27: 21296 | P27: 21828 | Q27: 22148 | R27: 21936 | S27: 22121 | T27: 21611 | U27: 21120 | V27: 21340 | W27: 21130 | X27: 21554 | Y27: 19746
A28: 21 | B28: 24263 | C28: 20780 | D28: 20983 | E28: 21824 | F28: 22654 | G28: 22364 | H28: 22541 | I28: 23379 | J28: 23485 | K28: 23618 | L28: 24165 | M28: 24616 | N28: 24946 | O28: 24985 | P28: 24667 | Q28: 24927 | R28: 25484 | S28: 25716 | T28: 25483 | U28: 25109 | V28: 24728 | W28: 24929 | X28: 24819 | Y28: 24964 | Z28: 22469
A29: 20 | B29: 24753 | C29: 22217 | D29: 22251 | E29: 23268 | F29: 24697 | G29: 24845 | H29: 24513 | I29: 24760 | J29: 25839 | K29: 25764 | L29: 25836 | M29: 26215 | N29: 26658 | O29: 27018 | P29: 26974 | Q29: 26802 | R29: 26598 | S29: 27188 | T29: 27182 | U29: 26920 | V29: 26748 | W29: 26074 | X29: 25961 | Y29: 25965 | Z29: 26080 | AA29: 23680
A30: 19 | B30: 18337 | C30: 15272 | D30: 15351 | E30: 16388 | F30: 17777 | G30: 17811 | H30: 17969 | I30: 17850 | J30: 17986 | K30: 18513 | L30: 18810 | M30: 18712 | N30: 19092 | O30: 19352 | P30: 19293 | Q30: 19311 | R30: 19279 | S30: 19224 | T30: 19841 | U30: 19412 | V30: 19496 | W30: 19006 | X30: 18565 | Y30: 18497 | Z30: 18574 | AA30: 18273 | AB30: 16686
A31: 18 | B31: 14603 | C31: 11581 | D31: 11601 | E31: 11814 | F31: 12585 | G31: 12515 | H31: 12663 | I31: 12756 | J31: 12484 | K31: 12565 | L31: 13105 | M31: 13137 | N31: 13152 | O31: 13221 | P31: 13232 | Q31: 13454 | R31: 13673 | S31: 13291 | T31: 13343 | U31: 13701 | V31: 13568 | W31: 13442 | X31: 13300 | Y31: 12901 | Z31: 12874 | AA31: 12848 | AB31: 12822 | AC31: 11553
A32: 17 | B32: 14565 | C32: 11745 | D32: 11525 | E32: 11933 | F32: 12284 | G32: 12351 | H32: 12607 | I32: 12981 | J32: 12886 | K32: 12545 | L32: 12608 | M32: 13070 | N32: 13009 | O32: 13126 | P32: 13196 | Q32: 13340 | R32: 13629 | S32: 13370 | T32: 13151 | U32: 13375 | V32: 13523 | W32: 13442 | X32: 13146 | Y32: 13052 | Z32: 12931 | AA32: 12918 | AB32: 12747 | AC32: 12675 | AD32: 11194
A33: 16 | B33: 14336 | C33: 11729 | D33: 11501 | E33: 11943 | F33: 12643 | G33: 12368 | H33: 12537 | I33: 12844 | J33: 13203 | K33: 13175 | L33: 12849 | M33: 12803 | N33: 13094 | O33: 13395 | P33: 13469 | Q33: 13463 | R33: 13558 | S33: 13857 | T33: 13660 | U33: 13230 | V33: 13148 | W33: 13518 | X33: 13549 | Y33: 13296 | Z33: 13023 | AA33: 12482 | AB33: 12559 | AC33: 12583 | AD33: 12556 | AE33: 11139
A34: 15 | B34: 27968 | C34: 19229 | D34: 24916 | E34: 33240 | F34: 39507 | G34: 39449 | H34: 39067 | I34: 39288 | J34: 40115 | K34: 40636 | L34: 40844 | M34: 40773 | N34: 41091 | O34: 41364 | P34: 41227 | Q34: 40659 | R34: 40981 | S34: 41499 | T34: 42180 | U34: 41534 | V34: 41131 | W34: 40778 | X34: 41286 | Y34: 41252 | Z34: 40838 | AA34: 40173 | AB34: 39367 | AC34: 39342 | AD34: 39291 | AE34: 39214 | AF34: 37341
A35: 14 | B35: 14311 | C35: 13311 | D35: 13217 | E35: 13745 | F35: 14554 | G35: 14736 | H35: 15062 | I35: 15127 | J35: 15393 | K35: 15766 | L35: 16005 | M35: 16165 | N35: 15877 | O35: 16088 | P35: 16055 | Q35: 16092 | R35: 16247 | S35: 16380 | T35: 16582 | U35: 16794 | V35: 16894 | W35: 16447 | X35: 16078 | Y35: 16632 | Z35: 16360 | AA35: 16640 | AB35: 16137 | AC35: 15953 | AD35: 15761 | AE35: 15791 | AF35: 15779 | AG35: 14510
A36: 13 | B36: 11567 | C36: 10284 | D36: 10173 | E36: 10269 | F36: 10753 | G36: 10737 | H36: 11183 | I36: 11327 | J36: 11370 | K36: 11527 | L36: 11843 | M36: 11915 | N36: 11977 | O36: 11729 | P36: 11906 | Q36: 11944 | R36: 12049 | S36: 11881 | T36: 11971 | U36: 12044 | V36: 12374 | W36: 12333 | X36: 12286 | Y36: 12151 | Z36: 12467 | AA36: 12246 | AB36: 12041 | AC36: 11830 | AD36: 11750 | AE36: 11576 | AF36: 11460 | AG36: 11520 | AH36: 10201
A37: 12 | B37: 14362 | C37: 10214 | D37: 11095 | E37: 11400 | F37: 11763 | G37: 11859 | H37: 12370 | I37: 13023 | J37: 13101 | K37: 13233 | L37: 13457 | M37: 13870 | N37: 14090 | O37: 14176 | P37: 14118 | Q37: 14122 | R37: 14276 | S37: 14259 | T37: 14494 | U37: 14540 | V37: 14694 | W37: 14859 | X37: 14854 | Y37: 14690 | Z37: 14610 | AA37: 15053 | AB37: 14708 | AC37: 14651 | AD37: 14762 | AE37: 14233 | AF37: 14230 | AG37: 13984 | AH37: 14062 | AI37: 12610
A38: 11 | B38: 18709 | C38: 12171 | D38: 11122 | E38: 12551 | F38: 13267 | G38: 13444 | H38: 13979 | I38: 14566 | J38: 15341 | K38: 15790 | L38: 15780 | M38: 16122 | N38: 16441 | O38: 17031 | P38: 17017 | Q38: 17089 | R38: 17203 | S38: 17192 | T38: 17156 | U38: 17511 | V38: 17641 | W38: 17801 | X38: 18054 | Y38: 18382 | Z38: 17990 | AA38: 17996 | AB38: 18562 | AC38: 18289 | AD38: 18072 | AE38: 17597 | AF38: 17318 | AG38: 17004 | AH38: 16838 | AI38: 16747 | AJ38: 15123
A39: 10 | B39: 21946 | C39: 18509 | D39: 18547 | E39: 18022 | F39: 19196 | G39: 19199 | H39: 19765 | I39: 20217 | J39: 20713 | K39: 21592 | L39: 21771 | M39: 21848 | N39: 22062 | O39: 22619 | P39: 22803 | Q39: 23088 | R39: 23006 | S39: 22618 | T39: 22920 | U39: 23313 | V39: 23305 | W39: 23528 | X39: 23889 | Y39: 24254 | Z39: 24242 | AA39: 23773 | AB39: 23594 | AC39: 23880 | AD39: 24047 | AE39: 23624 | AF39: 23468 | AG39: 22588 | AH39: 22447 | AI39: 22150 | AJ39: 22383 | AK39: 19236
A40: 9 | B40: 13502 | C40: 13377 | D40: 12784 | E40: 13084 | F40: 13110 | G40: 13172 | H40: 13548 | I40: 13704 | J40: 13892 | K40: 14094 | L40: 14838 | M40: 14752 | N40: 14610 | O40: 15108 | P40: 15080 | Q40: 15395 | R40: 15313 | S40: 15246 | T40: 15165 | U40: 15035 | V40: 15346 | W40: 15648 | X40: 15699 | Y40: 16067 | Z40: 16351 | AA40: 16024 | AB40: 16101 | AC40: 16094 | AD40: 16023 | AE40: 16103 | AF40: 16059 | AG40: 15553 | AH40: 14904 | AI40: 14764 | AJ40: 14957 | AK40: 14904 | AL40: 13300
...

Sheet results_1
A1: 1. Скільки листів у середньому надіслано одному користувачу:
A2: а) за 3 місяці з моменту встановлення додатку? | E2: б) за 6 місяців з моменту встановлення додатку? | I2: в) за 1 рік з моменту встановлення додатку?
A4: Сума листів за 12 тижнів | B4: Середня кількість листів на користувача | E4: Сума листів за 24 тижні | F4: Середня кількість листів на користувача | I4: Середня кількість листів за 1 рік | J4: =SUM('Emails sent'!C48:AT48)/'Emails sent'!B48 -> 678.19787
A5: =SUM('Emails sent'!C5:N5) -> 1227632 | B5: =A5/'Emails sent'!B5 -> 51.991869 | E5: =SUM('Emails sent'!C5:Z5) -> 1227632 | F5: =E5/'Emails sent'!B5 -> 51.991869
A6: =SUM('Emails sent'!C6:N6) -> 2438160 | B6: =A6/'Emails sent'!B6 -> 100.33167 | E6: =SUM('Emails sent'!C6:Z6) -> 2438160 | F6: =E6/'Emails sent'!B6 -> 100.33167
A7: =SUM('Emails sent'!C7:N7) -> 3425211 | B7: =A7/'Emails sent'!B7 -> 140.03316 | E7: =SUM('Emails sent'!C7:Z7) -> 3425211 | F7: =E7/'Emails sent'!B7 -> 140.03316
A8: =SUM('Emails sent'!C8:N8) -> 4265158 | B8: =A8/'Emails sent'!B8 -> 175.68719 | E8: =SUM('Emails sent'!C8:Z8) -> 4265158 | F8: =E8/'Emails sent'!B8 -> 175.68719
A9: =SUM('Emails sent'!C9:N9) -> 5268998 | B9: =A9/'Emails sent'!B9 -> 208.31843 | E9: =SUM('Emails sent'!C9:Z9) -> 5268998 | F9: =E9/'Emails sent'!B9 -> 208.31843
A10: =SUM('Emails sent'!C10:N10) -> 7375457 | B10: =A10/'Emails sent'!B10 -> 252.04897 | E10: =SUM('Emails sent'!C10:Z10) -> 7375457 | F10: =E10/'Emails sent'!B10 -> 252.04897
A11: =SUM('Emails sent'!C11:N11) -> 8173981 | B11: =A11/'Emails sent'!B11 -> 283.34654 | E11: =SUM('Emails sent'!C11:Z11) -> 8173981 | F11: =E11/'Emails sent'!B11 -> 283.34654
A12: =SUM('Emails sent'!C12:N12) -> 7182898 | B12: =A12/'Emails sent'!B12 -> 249.91817 | E12: =SUM('Emails sent'!C12:Z12) -> 7182898 | F12: =E12/'Emails sent'!B12 -> 249.91817
A13: =SUM('Emails sent'!C13:N13) -> 7109279 | B13: =A13/'Emails sent'!B13 -> 322.06573 | E13: =SUM('Emails sent'!C13:Z13) -> 7109279 | F13: =E13/'Emails sent'!B13 -> 322.06573
A14: =SUM('Emails sent'!C14:N14) -> 9554605 | B14: =A14/'Emails sent'!B14 -> 393.97184 | E14: =SUM('Emails sent'!C14:Z14) -> 9554605 | F14: =E14/'Emails sent'!B14 -> 393.97184
A15: =SUM('Emails sent'!C15:N15) -> 12777532 | B15: =A15/'Emails sent'!B15 -> 447.94152 | E15: =SUM('Emails sent'!C15:Z15) -> 12777532 | F15: =E15/'Emails sent'!B15 -> 447.94152
A16: =SUM('Emails sent'!C16:N16) -> 14916650 | B16: =A16/'Emails sent'!B16 -> 493.58559 | E16: =SUM('Emails sent'!C16:Z16) -> 14916650 | F16: =E16/'Emails sent'!B16 -> 493.58559
... A48: =SUM('Emails sent'!C48:N48) -> 5458635 | B48: =A48/'Emails sent'!B48 -> 297.13325 | E48: =SUM('Emails sent'!C48:Z48) -> 8920787 | F48: =E48/'Emails sent'!B48 -> 485.59071
A50: Середня кількість листів за 3 місяці | B50: =AVERAGE(B17:B48) -> 432.20083 | E50: Середня кількість листів за 6 місяців | F50: =AVERAGE(F30:F48) -> 513.11882

Sheet results_2-4
A1: 2. Скільки в середньому "живе" один користувач додатку? | C1: =1+SUM('Users Retention Rate'!C52:AT52) -> 12.86789 | G1: 4. Який середній CTR впродовж року для користувачів, які зареєструвались у проміжок: | I1: Сума кліків | J1: Кількість надісланих листів | K1: Середній CTR
G2: а) з 17 по 20 тиждень? | I2: =SUM('Emails clicks'!C29:AT32) -> 1821933 | J2: =SUM('Emails sent'!C29:AT32) -> 43142856 | K2: =I2/J2 -> 0.042230236
G3: б) з 21 по 24 тиждень? | I3: =SUM('Emails clicks'!C25:AT28) -> 2884461 | J3: =SUM('Emails sent'!C25:AT28) -> 73290032 | K3: =I3/J3 -> 0.039356798
G4: в) з 25 по 28 тиждень? | I4: =SUM('Emails clicks'!C21:AT24) -> 2021081 | J4: =SUM('Emails sent'!C21:AT24) -> 112582405 | K4: =I4/J4 -> 0.017952015
A5: 3. Виходячи з ціни за відправку листа в $0.1, скільки коштує утримання користувача за допомогою email розсилки впродовж одного року? | C5: =results_1!J4*0.1 -> 67.819787
